<?xml version="1.0" ?>
<robot name="fish_hpurv">
  <!-- Link: link_base -->
  <link name="link_base">
    <inertial>
      <origin xyz="0.0325815 0.0493006 -0.0204279" rpy="0 0 0"/>
      <mass value="50"/>
      <inertia ixx="0.01" ixy="0" ixz="0" iyy="0.01" iyz="0" izz="0.01"/>
    </inertial>
    <visual>
      <origin xyz="0.0325815 0.0493006 -0.0204279" rpy="0 0 0"/>
      <geometry>
        <mesh filename="$(find fish_hpurv)/meshes/link_base.stl"/>
      </geometry>
      <material name="link_base_material">
        <color rgba="0.796078 0.823529 0.937255 1.0"/>
      </material>
    </visual>
    <collision>
      <origin xyz="0.0325815 0.0493006 -0.0204279" rpy="0 0 0"/>
      <geometry>
        <mesh filename="$(find fish_hpurv)/meshes/link_base.stl"/>
      </geometry>
    </collision>
  </link>

  <!-- Link: link_caudal -->
  <link name="link_caudal">
    <inertial>
      <origin xyz="-0.378805 2.04697e-16 -0.05" rpy="1.5708 0 0"/>
      <mass value="10"/>
      <inertia ixx="0.005" ixy="0" ixz="0" iyy="0.005" iyz="0" izz="0.005"/>
    </inertial>
    <visual>
      <origin xyz="-0.378805 2.04697e-16 -0.05" rpy="1.5708 0 0"/>
      <geometry>
        <mesh filename="$(find fish_hpurv)/meshes/link_caudal.stl"/>
      </geometry>
      <material name="link_caudal_material">
        <color rgba="0.796078 0.823529 0.937255 1.0"/>
      </material>
    </visual>
    <collision>
      <origin xyz="-0.378805 2.04697e-16 -0.05" rpy="1.5708 0 0"/>
      <geometry>
        <mesh filename="$(find fish_hpurv)/meshes/link_caudal.stl"/>
      </geometry>
    </collision>
  </link>

  <!-- Joint: caudal_joint (from link_base to link_caudal) -->
  <joint name="caudal_joint" type="revolute">
    <origin xyz="0.425323 0.0803079 -0.0204279" rpy="-1.5708 0 0"/>
    <parent link="link_base"/>
    <child link="link_caudal"/>
    <axis xyz="0 0 1"/>
    <limit effort="10" velocity="10" lower="-0.523599" upper="0.523599"/>
  </joint>

  <!-- Link: link_pectoral_left -->
  <link name="link_pectoral_left">
    <inertial>
      <origin xyz="0.0829833 -0.0470575 0.13" rpy="3.14159 0 0"/>
      <mass value="5"/>
      <inertia ixx="0.001" ixy="0" ixz="0" iyy="0.001" iyz="0" izz="0.001"/>
    </inertial>
    <visual>
      <origin xyz="0.0829833 -0.0470575 0.13" rpy="3.14159 0 0"/>
      <geometry>
        <mesh filename="$(find fish_hpurv)/meshes/link_pectoral_left.stl"/>
      </geometry>
      <material name="link_pectoral_left_material">
        <color rgba="0.796078 0.823529 0.937255 1.0"/>
      </material>
    </visual>
    <collision>
      <origin xyz="0.0829833 -0.0470575 0.13" rpy="3.14159 0 0"/>
      <geometry>
        <mesh filename="$(find fish_hpurv)/meshes/link_pectoral_left.stl"/>
      </geometry>
    </collision>
  </link>

  <!-- Joint: joint1 (from link_base to link_pectoral_left) -->
  <joint name="joint1" type="revolute">
    <origin xyz="-0.0504018 0.00224307 0.118572" rpy="3.14159 0 0"/>
    <parent link="link_base"/>
    <child link="link_pectoral_left"/>
    <axis xyz="0 0 1"/>
    <limit effort="10" velocity="10" lower="-0.785398" upper="0.785398"/>
  </joint>

  <!-- Link: link_pectoral_right -->
  <link name="link_pectoral_right">
    <inertial>
      <origin xyz="0.0829833 0.0470575 0.13" rpy="0 0 0"/>
      <mass value="5"/>
      <inertia ixx="0.001" ixy="0" ixz="0" iyy="0.001" iyz="0" izz="0.001"/>
    </inertial>
    <visual>
      <origin xyz="0.0829833 0.0470575 0.13" rpy="0 0 0"/>
      <geometry>
        <mesh filename="$(find fish_hpurv)/meshes/link_pectoral_right.stl"/>
      </geometry>
      <material name="link_pectoral_right_material">
        <color rgba="0.796078 0.823529 0.937255 1.0"/>
      </material>
    </visual>
    <collision>
      <origin xyz="0.0829833 0.0470575 0.13" rpy="0 0 0"/>
      <geometry>
        <mesh filename="$(find fish_hpurv)/meshes/link_pectoral_right.stl"/>
      </geometry>
    </collision>
  </link>

  <!-- Joint: joint2 (from link_base to link_pectoral_right) -->
  <joint name="joint2" type="revolute">
    <origin xyz="-0.0504018 0.00224307 -0.160428" rpy="0 0 0"/>
    <parent link="link_base"/>
    <child link="link_pectoral_right"/>
    <axis xyz="0 0 1"/>
    <limit effort="10" velocity="10" lower="-0.785398" upper="0.785398"/>
  </joint>

  <!-- Gazebo Plugin for Buoyancy -->
  <gazebo>
    <plugin name="buoyancy_plugin" filename="libBuoyancyPlugin.so">
      <fluid_density>1000</fluid_density>
      <link name="link_base">
        <volume>0.05</volume>
        <center_of_volume>0.0325815 0.0493006 -0.0204279</center_of_volume>
      </link>
      <link name="link_caudal">
        <volume>0.03</volume>
        <center_of_volume>-0.378805 0  -0.05</center_of_volume>
      </link>
      <link name="link_pectoral_left">
        <volume>0.01</volume>
        <center_of_volume>0.0829833 -0.0470575 0.13</center_of_volume>
      </link>
      <link name="link_pectoral_right">
        <volume>0.01</volume>
        <center_of_volume>0.0829833 0.0470575 0.13</center_of_volume>
      </link>
    </plugin>
  </gazebo>
</robot>
